
https://www.pythonanywhere.com/user/autouploadoninsta/account/#:~:text=Specific%20sites%20via%0AHTTP(S)%20only
https://www.pythonanywhere.com/user/autouploadoninsta/files/var/log/schedule-log-404256.log

 cnn
Traceback (most recent call last):
  File "/usr/local/lib/python3.10/site-packages/urllib3/connectionpool.py", line 700, in urlopen
    self._prepare_proxy(conn)
  File "/usr/local/lib/python3.10/site-packages/urllib3/connectionpool.py", line 994, in _prepare_proxy
    conn.connect()
  File "/usr/local/lib/python3.10/site-packages/urllib3/connection.py", line 369, in connect
    self._tunnel()
  File "/usr/local/lib/python3.10/http/client.py", line 924, in _tunnel
    raise OSError(f"Tunnel connection failed: {code} {message.strip()}")
OSError: Tunnel connection failed: 403 Forbidden

During handling of the above exception, another exception occurred:

Traceback (most recent call last):
  File "/home/autouploadoninsta/.local/lib/python3.10/site-packages/requests/adapters.py", line 486, in send
    resp = conn.urlopen(
  File "/usr/local/lib/python3.10/site-packages/urllib3/connectionpool.py", line 785, in urlopen
    retries = retries.increment(
  File "/usr/local/lib/python3.10/site-packages/urllib3/util/retry.py", line 592, in increment
    raise MaxRetryError(_pool, url, error or ResponseError(cause))
urllib3.exceptions.MaxRetryError: HTTPSConnectionPool(host='mastodon.social', port=443): Max retries exceeded with url: /api/v1/statuses (Caused by ProxyError('Cannot connect to proxy.', OSError('Tunnel connection failed: 403 Forbidden')))

During handling of the above exception, another exception occurred:

Traceback (most recent call last):
  File "/home/autouploadoninsta/flask_app.py", line 32, in <module>
    r = requests.post(url, data=params, headers=auth)
  File "/home/autouploadoninsta/.local/lib/python3.10/site-packages/requests/api.py", line 115, in post
    return request("post", url, data=data, json=json, **kwargs)
  File "/home/autouploadoninsta/.local/lib/python3.10/site-packages/requests/api.py", line 59, in request
    return session.request(method=method, url=url, **kwargs)
  File "/home/autouploadoninsta/.local/lib/python3.10/site-packages/requests/sessions.py", line 589, in request
    resp = self.send(prep, **send_kwargs)
  File "/home/autouploadoninsta/.local/lib/python3.10/site-packages/requests/sessions.py", line 703, in send
    r = adapter.send(request, **kwargs)
  File "/home/autouploadoninsta/.local/lib/python3.10/site-packages/requests/adapters.py", line 513, in send
    raise ProxyError(e, request=request)
requests.exceptions.ProxyError: HTTPSConnectionPool(host='mastodon.social', port=443): Max retries exceeded with url: /api/v1/statuses (Caused by ProxyError('Cannot connect to proxy.', OSError('Tunnel connection failed: 403 Forbidden')))

2023-11-29 02:10:17 -- Completed task, took 9.48 seconds, return code was 1.


